Workbook

Sheet 01_Capa
B2: FINANCE OPS & ANALYTICS
B3: Modelo Financeiro Gerencial — Empresa Beauty Omnichannel
B5: Período: | C5: Jan/2023 a Dez/2024 (24 meses)
B6: Canais: | C6: E-commerce · Marketplace · Franquia · Loja Própria
B7: Categorias: | C7: Skincare · Maquiagem · Perfumes · Haircare
B8: SKUs: | C8: 58 produtos ativos
B9: Receita líquida 24m: | C9: R$ 3,99 MM (média mensal R$ 166,5 k)
B10: Status do modelo: | C10: Operação em virada — break-even cruzado em Nov-Dez/2024
B12: ÍNDICE DE ABAS
B13: 02_Premissas | C13: Parâmetros editáveis do modelo (tributos, forecast, BPO)
B14: 03_Base_Vendas | C14: Base agregada de vendas: 24m × 4 canais × 4 categorias
B15: 04_Base_Despesas | C15: Base agregada de despesas operacionais por categoria
B16: 05_Base_Apoio | C16: Pagamentos, estoque, clientes e calendário
B17: 06_DRE_Consolidada | C17: DRE gerencial mensal — receita até EBITDA e resultado
B18: 07_DRE_por_Canal | C18: DRE replicada para cada canal de venda
B19: 08_DRE_por_Categoria | C19: DRE replicada para cada categoria de produto
B20: 09_Fluxo_de_Caixa | C20: Fluxo de caixa operacional pelos métodos direto e indireto
B21: 10_Capital_de_Giro | C21: PMR · PMP · PME · NCG · ciclo financeiro
B22: 11_Estoque_e_Giro | C22: Aging, cobertura e giro de estoque por categoria
B23: 12_KPIs | C23: Painel de indicadores financeiros e operacionais
B24: 13_Forecast_6M | C24: Projeção simplificada do 1º semestre de 2025
... B26: 15_Dashboard_Exec | C26: Visão executiva consolidada com gráficos
B29: LEGENDA DE CORES
B30: Texto azul | C30: Input editável (premissa, parâmetro)
B31: Texto preto | C31: Fórmula / cálculo
B32: Texto verde | C32: Link entre abas
B33: Fundo amarelo | C33: Premissa-chave (revisar com frequência)
B34: Fundo verde | C34: Resultado favorável
B35: Fundo vermelho | C35: Resultado desfavorável / alerta
B38: Modelo gerencial. Tributos federais/estaduais não inclusos: receita líquida = receita bruta − devoluções − comissões de canal.

Sheet 02_Premissas
A2: 02 — PREMISSAS DO MODELO
A3: Parâmetros editáveis em azul. Alterações recalculam todas as abas.
A5: Forecast — Crescimento mensal projetado (média móvel × premissa)
B6: Canal | C6: Crescimento (%a.m.) | D6: Janela média (meses) | G6: Observação
B7: E-commerce | C7: 0.025 | D7: 3 | G7: canal com maior elasticidade — alvo de tração
B8: Marketplace | C8: 0.015 | D8: 3 | G8: crescimento moderado, dependente de comissão
B9: Franquia | C9: 0.01 | D9: 3 | G9: expansão controlada, novas unidades em ramp-up
B10: Loja Própria | C10: 0.008 | D10: 3 | G10: footprint físico estável, foco em produtividade
A12: Inflação aplicada às despesas no forecast
B13: Inflação mensal | C13: 0.005 | G13: ≈ 6,2% a.a. — proxy IPCA
A15: Sazonalidade — fatores aplicados ao forecast por mês
B16: Mês | C16: Fator (1.0 = neutro) | G16: Observação
B17: Jan | C17: 0.95 | G17: pós-festas
B18: Fev | C18: 0.9 | G18: mês curto, baixa
B19: Mar | C19: 1 | G19: neutro
B20: Abr | C20: 0.95 | G20: neutro/baixa
B21: Mai | C21: 1.2 | G21: Dia das Mães — alta
B22: Jun | C22: 1.05 | G22: Namorados
A24: Antes vs Depois — premissas do projeto de transformação
B25: Métrica | C25: Antes | D25: Depois | G25: Observação
B26: Prazo de fechamento (dias úteis) | C26: 12 | D26: 5 | G26: Redução de 7 dias por fechamento
B27: Horas/mês — analista financeiro | C27: 200 | D27: 80 | G27: Liberação de capacidade analítica
B28: Custo médio R$/hora analista | C28: 85 | D28: 85 | G28: Custo total (folha + encargos)
B29: Lançamentos retrabalho/mês | C29: 12 | D29: 2 | G29: Erros pós-fechamento que retornam
B30: Tempo médio retrabalho (h) | C30: 4 | D30: 4 | G30: Hora analista por lançamento
B31: Divergências gateway × ERP/mês | C31: 7 | D31: 1 | G31: Captura automática vs revisão manual
B32: Comentários executivos manuais (h) | C32: 16 | D32: 4 | G32: Geração por IA acelera narrativa
A34: Definições contábeis
B35: Definição de Receita Líquida | C35: Receita bruta − devoluções − comissões de canal
B36: Tratamento de tributos | C36: Não inclusos no modelo gerencial (receita líquida ≈ líquida de canal)
B37: Custo dos Produtos Vendidos | C37: Custo médio ponderado por lote × quantidade (proxy contábil)
B38: EBITDA | C38: Margem contribuição − despesas operacionais (excl. depreciação e financeiro)
B39: EBIT | C39: EBITDA − depreciação
B40: Resultado Operacional | C40: EBIT − despesas financeiras

Sheet 03_Base_Vendas
A1: 03 — BASE: VENDAS AGREGADAS
A2: Agregação mensal por canal × categoria. Fonte das fórmulas das DREs.
A4: ano_mes | B4: canal | C4: categoria | D4: qtd_transacoes | E4: unidades | F4: receita_bruta | G4: devolucoes | H4: comissoes | I4: receita_liquida | J4: cmv | K4: margem_contrib | L4: qtd_devolvidas
A5: 2023-01 | B5: ecommerce | C5: haircare | D5: 41 | E5: 69 | F5: 8597.49 | G5: 617.67 | H5: 348.15 | I5: 7631.67 | J5: 4432.72 | K5: 3198.95 | L5: 3
A6: 2023-01 | B6: ecommerce | C6: maquiagem | D6: 70 | E6: 118 | F6: 10380.29 | G6: 172.73 | H6: 419.55 | I6: 9788.01 | J6: 4971.72 | K6: 4816.29 | L6: 1
A7: 2023-01 | B7: ecommerce | C7: perfumes | D7: 45 | E7: 89 | F7: 26995.05 | G7: 222.15 | H7: 1114.33 | I7: 25658.57 | J7: 14398.67 | K7: 11259.9 | L7: 1
A8: 2023-01 | B8: ecommerce | C8: skincare | D8: 68 | E8: 120 | F8: 22663.36 | G8: 929.98 | H8: 924.52 | I8: 20808.86 | J8: 8921.7 | K8: 11887.16 | L8: 3
A9: 2023-01 | B9: franquia | C9: haircare | D9: 14 | E9: 24 | F9: 2876.06 | G9: 0 | H9: 348.81 | I9: 2527.25 | J9: 1428.66 | K9: 1098.59 | L9: 0
A10: 2023-01 | B10: franquia | C10: maquiagem | D10: 36 | E10: 65 | F10: 6919.04 | G10: 302.34 | H10: 824.63 | I10: 5792.07 | J10: 3293.41 | K10: 2498.66 | L10: 3
A11: 2023-01 | B11: franquia | C11: perfumes | D11: 30 | E11: 57 | F11: 17868.8 | G11: 1649.8 | H11: 2160.58 | I11: 14058.42 | J11: 9400.91 | K11: 4657.51 | L11: 3
A12: 2023-01 | B12: franquia | C12: skincare | D12: 36 | E12: 61 | F12: 11997.82 | G12: 687.83 | H12: 1442.28 | I12: 9867.71 | J12: 4717.14 | K12: 5150.57 | L12: 2
A13: 2023-01 | B13: loja_propria | C13: haircare | D13: 10 | E13: 14 | F13: 1619.46 | G13: 0 | H13: 0.37 | I13: 1619.09 | J13: 855.15 | K13: 763.94 | L13: 0
A14: 2023-01 | B14: loja_propria | C14: maquiagem | D14: 24 | E14: 44 | F14: 3703.68 | G14: 0 | H14: 1.04 | I14: 3702.64 | J14: 1779.71 | K14: 1922.93 | L14: 0
A15: 2023-01 | B15: loja_propria | C15: perfumes | D15: 10 | E15: 15 | F15: 3841.65 | G15: 0 | H15: 2.38 | I15: 3839.27 | J15: 2007.8 | K15: 1831.47 | L15: 0
A16: 2023-01 | B16: loja_propria | C16: skincare | D16: 23 | E16: 38 | F16: 6122.39 | G16: 0 | H16: 0.37 | I16: 6122.02 | J16: 2487.69 | K16: 3634.33 | L16: 0
... A388: 2024-12 | B388: marketplace | C388: skincare | D388: 83 | E388: 162 | F388: 31199.98 | G388: 4631.1 | H388: 5322.54 | I388: 21246.34 | J388: 12451.85 | K388: 8794.49 | L388: 9

Sheet 04_Base_Despesas
A1: 04 — BASE: DESPESAS AGREGADAS
A2: Despesas operacionais por categoria, com competência mensal.
A4: ano_mes | B4: categoria | C4: qtd | D4: valor
A5: 2023-01 | B5: administrativo | C5: 4 | D5: 4109.09
A6: 2023-01 | B6: aluguel | C6: 5 | D6: 9500.01
A7: 2023-01 | B7: depreciacao | C7: 3 | D7: 2199.99
A8: 2023-01 | B8: financeiro | C8: 1 | D8: 1365.44
A9: 2023-01 | B9: logistica | C9: 4 | D9: 8993.95
A10: 2023-01 | B10: marketing | C10: 2 | D10: 17846.39
A11: 2023-01 | B11: outros | C11: 2 | D11: 791.43
A12: 2023-01 | B12: pessoal | C12: 5 | D12: 50652.31
A13: 2023-01 | B13: tecnologia | C13: 6 | D13: 6715.05
A14: 2023-02 | B14: administrativo | C14: 1 | D14: 2500
A15: 2023-02 | B15: aluguel | C15: 3 | D15: 9500
A16: 2023-02 | B16: depreciacao | C16: 2 | D16: 2200
... A220: 2024-12 | B220: tecnologia | C220: 3 | D220: 6596.33
A223: Visão alternativa — Despesas por Centro de Custo
A224: ano_mes | B224: centro_custo | C224: qtd | D224: valor
A225: 2023-01 | B225: administrativo | C225: 1 | D225: 27719.13
A226: 2023-01 | B226: armazenagem | C226: 3 | D226: 2907.87
A227: 2023-01 | B227: ativos | C227: 3 | D227: 2199.99
A228: 2023-01 | B228: comercial | C228: 1 | D228: 13995.72
A229: 2023-01 | B229: contabilidade | C229: 3 | D229: 2499.99
A230: 2023-01 | B230: digital | C230: 1 | D230: 14164.74
A231: 2023-01 | B231: erp_gateway | C231: 3 | D231: 2199.99
A232: 2023-01 | B232: estoque | C232: 2 | D232: 3000
A233: 2023-01 | B233: frete_saida | C233: 1 | D233: 6086.08
A234: 2023-01 | B234: juridico | C234: 1 | D234: 1609.1
A235: 2023-01 | B235: logistica | C235: 3 | D235: 8937.46
A236: 2023-01 | B236: operacional | C236: 3 | D236: 6500.01
... A601: 2024-12 | B601: varios | C601: 1 | D601: 648.47

Sheet 05_Base_Apoio
A1: 05 — BASES DE APOIO
A2: Pagamentos, estoque, clientes e calendário consolidados.
A4: Pagamentos por canal × mês (PMR e taxas)
A5: ano_mes | B5: canal | C5: qtd | D5: valor_bruto | E5: valor_erp | F5: taxa_total | G5: divergencia | H5: prazo_gateway_med | I5: prazo_erp_med
A6: 2023-01 | B6: ecommerce | C6: 1 | D6: 63887.11 | E6: 62698.31 | F6: 951.92 | G6: -236.88 | H6: 2 | I6: 14
A7: 2023-01 | B7: franquia | C7: 1 | D7: 32245.45 | E7: 32681.45 | F7: 0 | G7: 436 | H7: 0 | I7: 21
A8: 2023-01 | B8: loja_propria | C8: 1 | D8: 15283.02 | E8: 14978.34 | F8: 349.98 | G8: 45.3 | H8: 1 | I8: 3
A9: 2023-01 | B9: marketplace | C9: 1 | D9: 38606.57 | E9: 37838.3 | F9: 768.27 | G9: 0 | H9: 2 | I9: 30
A10: 2023-02 | B10: ecommerce | C10: 1 | D10: 59873.22 | E10: 59276.02 | F10: 892.11 | G10: 294.91 | H10: 2 | I10: 14
A11: 2023-02 | B11: franquia | C11: 1 | D11: 17813.16 | E11: 17813.16 | F11: 0 | G11: 0 | H11: 0 | I11: 21
A12: 2023-02 | B12: loja_propria | C12: 1 | D12: 16586.45 | E12: 16206.62 | F12: 379.83 | G12: 0 | H12: 1 | I12: 3
A13: 2023-02 | B13: marketplace | C13: 1 | D13: 30438.67 | E13: 29832.94 | F13: 605.73 | G13: 0 | H13: 2 | I13: 30
A14: 2023-03 | B14: ecommerce | C14: 1 | D14: 65382.53 | E14: 64408.33 | F14: 974.2 | G14: 0 | H14: 2 | I14: 14
A15: 2023-03 | B15: franquia | C15: 1 | D15: 22666.4 | E15: 22666.4 | F15: 0 | G15: 0 | H15: 0 | I15: 21
A16: 2023-03 | B16: loja_propria | C16: 1 | D16: 22127.87 | E16: 21621.14 | F16: 506.73 | G16: 0 | H16: 1 | I16: 3
A17: 2023-03 | B17: marketplace | C17: 1 | D17: 41925 | E17: 41090.69 | F17: 834.31 | G17: 0 | H17: 2 | I17: 30
... A101: 2024-12 | B101: marketplace | C101: 1 | D101: 53544.75 | E101: 51783.47 | F101: 1065.54 | G101: -695.74 | H101: 2 | I101: 30
A104: Receita líquida por tipo de compra (recorrente vs pontual)
A105: ano_mes | B105: canal | C105: recorrente | D105: pontual
A106: 2023-01 | B106: ecommerce | C106: 13459.69 | D106: 50427.42
A107: 2023-01 | B107: franquia | C107: 11086.46 | D107: 21158.99
A108: 2023-01 | B108: loja_propria | C108: 4673.91 | D108: 10609.11
A109: 2023-01 | B109: marketplace | C109: 14283.4 | D109: 24323.17
A110: 2023-02 | B110: ecommerce | C110: 14781.29 | D110: 45091.93
A111: 2023-02 | B111: franquia | C111: 3254.25 | D111: 14558.91
A112: 2023-02 | B112: loja_propria | C112: 5465.85 | D112: 11120.6
A113: 2023-02 | B113: marketplace | C113: 10966.61 | D113: 19472.06
A114: 2023-03 | B114: ecommerce | C114: 18029.01 | D114: 47353.52
A115: 2023-03 | B115: franquia | C115: 6158.79 | D115: 16507.61
A116: 2023-03 | B116: loja_propria | C116: 6647.19 | D116: 15480.68
A117: 2023-03 | B117: marketplace | C117: 14649.28 | D117: 27275.72
... A201: 2024-12 | B201: marketplace | C201: 17350.77 | D201: 36193.98
A204: Estoque — aging por categoria × status
A205: categoria | B205: status_aging | C205: qtd_lotes | D205: unidades | E205: valor | F205: aging_med
A206: haircare | B206: alerta | C206: 6 | D206: 725 | E206: 68709.52 | F206: 266.33
A207: haircare | B207: critico | C207: 21 | D207: 2955 | E207: 196907.02 | F207: 538.24
A208: haircare | B208: normal | C208: 4 | D208: 659 | E208: 44088.54 | F208: 146.5
A209: maquiagem | B209: alerta | C209: 6 | D209: 628 | E209: 25048.84 | F209: 278.33
A210: maquiagem | B210: critico | C210: 31 | D210: 4939 | E210: 232641.52 | F210: 538.13
A211: maquiagem | B211: normal | C211: 16 | D211: 2327 | E211: 103523.36 | F211: 88.5
...

Sheet 06_DRE_Consolidada
A1: 06 — DRE GERENCIAL CONSOLIDADA
A2: Demonstrativo mensal completo: receita até resultado operacional. Total acumulado em Z.
A4: DRE Consolidada — toda a operação
A5: Item | B5: 2023-01 | C5: 2023-02 | D5: 2023-03 | E5: 2023-04 | F5: 2023-05 | G5: 2023-06 | H5: 2023-07 | I5: 2023-08 | J5: 2023-09 | K5: 2023-10 | L5: 2023-11 | M5: 2023-12 | N5: 2024-01 | O5: 2024-02 | P5: 2024-03 | Q5: 2024-04 | R5: 2024-05 | S5: 2024-06 | T5: 2024-07 | U5: 2024-08 | V5: 2024-09 | W5: 2024-10 | X5: 2024-11 | Y5: 2024-12 | Z5: Total 24m
A6: Receita Bruta | B6: =SUMIFS('03_Base_Vendas'!$F$4:$F$387, '03_Base_Vendas'!$A$4:$A$387, B$5) -> 171628.88 | C6: =SUMIFS('03_Base_Vendas'!$F$4:$F$387, '03_Base_Vendas'!$A$4:$A$387, C$5) -> 144550.49 | D6: =SUMIFS('03_Base_Vendas'!$F$4:$F$387, '03_Base_Vendas'!$A$4:$A$387, D$5) -> 173089.52 | E6: =SUMIFS('03_Base_Vendas'!$F$4:$F$387, '03_Base_Vendas'!$A$4:$A$387, E$5) -> 159990.02 | F6: =SUMIFS('03_Base_Vendas'!$F$4:$F$387, '03_Base_Vendas'!$A$4:$A$387, F$5) -> 221309.94 | G6: =SUMIFS('03_Base_Vendas'!$F$4:$F$387, '03_Base_Vendas'!$A$4:$A$387, G$5) -> 191441.59 | H6: =SUMIFS('03_Base_Vendas'!$F$4:$F$387, '03_Base_Vendas'!$A$4:$A$387, H$5) -> 145485.14 | I6: =SUMIFS('03_Base_Vendas'!$F$4:$F$387, '03_Base_Vendas'!$A$4:$A$387, I$5) -> 149405.39 | ... Y6: =SUMIFS('03_Base_Vendas'!$F$4:$F$387, '03_Base_Vendas'!$A$4:$A$387, Y$5) -> 216126.54 | Z6: =SUM(B6:Y6) -> 4540779.6
A7: (−) Devoluções | B7: =SUMIFS('03_Base_Vendas'!$G$4:$G$387, '03_Base_Vendas'!$A$4:$A$387, B$5) -> 5827.19 | C7: =SUMIFS('03_Base_Vendas'!$G$4:$G$387, '03_Base_Vendas'!$A$4:$A$387, C$5) -> 8046.66 | D7: =SUMIFS('03_Base_Vendas'!$G$4:$G$387, '03_Base_Vendas'!$A$4:$A$387, D$5) -> 5842.25 | E7: =SUMIFS('03_Base_Vendas'!$G$4:$G$387, '03_Base_Vendas'!$A$4:$A$387, E$5) -> 6773.99 | F7: =SUMIFS('03_Base_Vendas'!$G$4:$G$387, '03_Base_Vendas'!$A$4:$A$387, F$5) -> 7918.41 | G7: =SUMIFS('03_Base_Vendas'!$G$4:$G$387, '03_Base_Vendas'!$A$4:$A$387, G$5) -> 6477.23 | H7: =SUMIFS('03_Base_Vendas'!$G$4:$G$387, '03_Base_Vendas'!$A$4:$A$387, H$5) -> 4353.16 | I7: =SUMIFS('03_Base_Vendas'!$G$4:$G$387, '03_Base_Vendas'!$A$4:$A$387, I$5) -> 8190.88 | ... Y7: =SUMIFS('03_Base_Vendas'!$G$4:$G$387, '03_Base_Vendas'!$A$4:$A$387, Y$5) -> 5236.03 | Z7: =SUM(B7:Y7) -> 176614.95
A8: (−) Comissões de canal | B8: =SUMIFS('03_Base_Vendas'!$H$4:$H$387, '03_Base_Vendas'!$A$4:$A$387, B$5) -> 15779.54 | C8: =SUMIFS('03_Base_Vendas'!$H$4:$H$387, '03_Base_Vendas'!$A$4:$A$387, C$5) -> 11792.33 | D8: =SUMIFS('03_Base_Vendas'!$H$4:$H$387, '03_Base_Vendas'!$A$4:$A$387, D$5) -> 15145.47 | E8: =SUMIFS('03_Base_Vendas'!$H$4:$H$387, '03_Base_Vendas'!$A$4:$A$387, E$5) -> 13399.87 | F8: =SUMIFS('03_Base_Vendas'!$H$4:$H$387, '03_Base_Vendas'!$A$4:$A$387, F$5) -> 18396.28 | G8: =SUMIFS('03_Base_Vendas'!$H$4:$H$387, '03_Base_Vendas'!$A$4:$A$387, G$5) -> 15242.06 | H8: =SUMIFS('03_Base_Vendas'!$H$4:$H$387, '03_Base_Vendas'!$A$4:$A$387, H$5) -> 11923.25 | I8: =SUMIFS('03_Base_Vendas'!$H$4:$H$387, '03_Base_Vendas'!$A$4:$A$387, I$5) -> 12269.8 | ... Y8: =SUMIFS('03_Base_Vendas'!$H$4:$H$387, '03_Base_Vendas'!$A$4:$A$387, Y$5) -> 16615.29 | Z8: =SUM(B8:Y8) -> 389110.95
A9: Receita Líquida | B9: =B6-B7-B8 -> 150022.15 | C9: =C6-C7-C8 -> 124711.5 | D9: =D6-D7-D8 -> 152101.8 | E9: =E6-E7-E8 -> 139816.16 | F9: =F6-F7-F8 -> 194995.25 | G9: =G6-G7-G8 -> 169722.3 | H9: =H6-H7-H8 -> 129208.73 | I9: =I6-I7-I8 -> 128944.71 | ... Y9: =Y6-Y7-Y8 -> 194275.22 | Z9: =SUM(B9:Y9) -> 3975053.7
A10: (−) CMV | B10: =SUMIFS('03_Base_Vendas'!$J$4:$J$387, '03_Base_Vendas'!$A$4:$A$387, B$5) -> 81211.09 | C10: =SUMIFS('03_Base_Vendas'!$J$4:$J$387, '03_Base_Vendas'!$A$4:$A$387, C$5) -> 68953.1 | D10: =SUMIFS('03_Base_Vendas'!$J$4:$J$387, '03_Base_Vendas'!$A$4:$A$387, D$5) -> 83570.01 | E10: =SUMIFS('03_Base_Vendas'!$J$4:$J$387, '03_Base_Vendas'!$A$4:$A$387, E$5) -> 75794.19 | F10: =SUMIFS('03_Base_Vendas'!$J$4:$J$387, '03_Base_Vendas'!$A$4:$A$387, F$5) -> 104404.86 | G10: =SUMIFS('03_Base_Vendas'!$J$4:$J$387, '03_Base_Vendas'!$A$4:$A$387, G$5) -> 93680.99 | H10: =SUMIFS('03_Base_Vendas'!$J$4:$J$387, '03_Base_Vendas'!$A$4:$A$387, H$5) -> 70276.95 | I10: =SUMIFS('03_Base_Vendas'!$J$4:$J$387, '03_Base_Vendas'!$A$4:$A$387, I$5) -> 70294.68 | ... Y10: =SUMIFS('03_Base_Vendas'!$J$4:$J$387, '03_Base_Vendas'!$A$4:$A$387, Y$5) -> 105108.86 | Z10: =SUM(B10:Y10) -> 2178990.1
A11: Margem de Contribuição | B11: =B9-B10 -> 68811.06 | C11: =C9-C10 -> 55758.4 | D11: =D9-D10 -> 68531.79 | E11: =E9-E10 -> 64021.97 | F11: =F9-F10 -> 90590.39 | G11: =G9-G10 -> 76041.31 | H11: =H9-H10 -> 58931.78 | I11: =I9-I10 -> 58650.03 | ... Y11: =Y9-Y10 -> 89166.36 | Z11: =SUM(B11:Y11) -> 1796063.6
A12: % Margem de Contribuição | B12: =IFERROR(B11/B9,0) -> 0.45867267 | C12: =IFERROR(C11/C9,0) -> 0.4470991 | D12: =IFERROR(D11/D9,0) -> 0.45056528 | E12: =IFERROR(E11/E9,0) -> 0.45790108 | F12: =IFERROR(F11/F9,0) -> 0.46457742 | G12: =IFERROR(G11/G9,0) -> 0.4480337 | H12: =IFERROR(H11/H9,0) -> 0.45609751 | I12: =IFERROR(I11/I9,0) -> 0.45484634 | ... Y12: =IFERROR(Y11/Y9,0) -> 0.45896929 | Z12: =IFERROR($Z$11/$Z$9,0) -> 0.4518338
A13: (−) Pessoal | B13: =SUMIFS('04_Base_Despesas'!$D$4:$D$219, '04_Base_Despesas'!$A$4:$A$219, B$5, '04_Base_Despesas'!$B$4:$B$219, "pessoal") -> 50652.31 | C13: =SUMIFS('04_Base_Despesas'!$D$4:$D$219, '04_Base_Despesas'!$A$4:$A$219, C$5, '04_Base_Despesas'!$B$4:$B$219, "pessoal") -> 52124.12 | D13: =SUMIFS('04_Base_Despesas'!$D$4:$D$219, '04_Base_Despesas'!$A$4:$A$219, D$5, '04_Base_Despesas'!$B$4:$B$219, "pessoal") -> 50124.75 | E13: =SUMIFS('04_Base_Despesas'!$D$4:$D$219, '04_Base_Despesas'!$A$4:$A$219, E$5, '04_Base_Despesas'!$B$4:$B$219, "pessoal") -> 49472.83 | F13: =SUMIFS('04_Base_Despesas'!$D$4:$D$219, '04_Base_Despesas'!$A$4:$A$219, F$5, '04_Base_Despesas'!$B$4:$B$219, "pessoal") -> 51984.88 | G13: =SUMIFS('04_Base_Despesas'!$D$4:$D$219, '04_Base_Despesas'!$A$4:$A$219, G$5, '04_Base_Despesas'!$B$4:$B$219, "pessoal") -> 50582.85 | H13: =SUMIFS('04_Base_Despesas'!$D$4:$D$219, '04_Base_Despesas'!$A$4:$A$219, H$5, '04_Base_Despesas'!$B$4:$B$219, "pessoal") -> 51882.99 | I13: =SUMIFS('04_Base_Despesas'!$D$4:$D$219, '04_Base_Despesas'!$A$4:$A$219, I$5, '04_Base_Despesas'!$B$4:$B$219, "pessoal") -> 51904.5 | ... Y13: =SUMIFS('04_Base_Despesas'!$D$4:$D$219, '04_Base_Despesas'!$A$4:$A$219, Y$5, '04_Base_Despesas'!$B$4:$B$219, "pessoal") -> 51109.32 | Z13: =SUM(B13:Y13) -> 1232369.6
A14: (−) Aluguel | B14: =SUMIFS('04_Base_Despesas'!$D$4:$D$219, '04_Base_Despesas'!$A$4:$A$219, B$5, '04_Base_Despesas'!$B$4:$B$219, "aluguel") -> 9500.01 | C14: =SUMIFS('04_Base_Despesas'!$D$4:$D$219, '04_Base_Despesas'!$A$4:$A$219, C$5, '04_Base_Despesas'!$B$4:$B$219, "aluguel") -> 9500 | D14: =SUMIFS('04_Base_Despesas'!$D$4:$D$219, '04_Base_Despesas'!$A$4:$A$219, D$5, '04_Base_Despesas'!$B$4:$B$219, "aluguel") -> 9500 | E14: =SUMIFS('04_Base_Despesas'!$D$4:$D$219, '04_Base_Despesas'!$A$4:$A$219, E$5, '04_Base_Despesas'!$B$4:$B$219, "aluguel") -> 9500 | F14: =SUMIFS('04_Base_Despesas'!$D$4:$D$219, '04_Base_Despesas'!$A$4:$A$219, F$5, '04_Base_Despesas'!$B$4:$B$219, "aluguel") -> 9500 | G14: =SUMIFS('04_Base_Despesas'!$D$4:$D$219, '04_Base_Despesas'!$A$4:$A$219, G$5, '04_Base_Despesas'!$B$4:$B$219, "aluguel") -> 9500 | H14: =SUMIFS('04_Base_Despesas'!$D$4:$D$219, '04_Base_Despesas'!$A$4:$A$219, H$5, '04_Base_Despesas'!$B$4:$B$219, "aluguel") -> 9500 | I14: =SUMIFS('04_Base_Despesas'!$D$4:$D$219, '04_Base_Despesas'!$A$4:$A$219, I$5, '04_Base_Despesas'!$B$4:$B$219, "aluguel") -> 9500 | ... Y14: =SUMIFS('04_Base_Despesas'!$D$4:$D$219, '04_Base_Despesas'!$A$4:$A$219, Y$5, '04_Base_Despesas'!$B$4:$B$219, "aluguel") -> 9500.01 | Z14: =SUM(B14:Y14) -> 228000.06
A15: (−) Marketing | B15: =SUMIFS('04_Base_Despesas'!$D$4:$D$219, '04_Base_Despesas'!$A$4:$A$219, B$5, '04_Base_Despesas'!$B$4:$B$219, "marketing") -> 17846.39 | C15: =SUMIFS('04_Base_Despesas'!$D$4:$D$219, '04_Base_Despesas'!$A$4:$A$219, C$5, '04_Base_Despesas'!$B$4:$B$219, "marketing") -> 12148.23 | D15: =SUMIFS('04_Base_Despesas'!$D$4:$D$219, '04_Base_Despesas'!$A$4:$A$219, D$5, '04_Base_Despesas'!$B$4:$B$219, "marketing") -> 10991.08 | E15: =SUMIFS('04_Base_Despesas'!$D$4:$D$219, '04_Base_Despesas'!$A$4:$A$219, E$5, '04_Base_Despesas'!$B$4:$B$219, "marketing") -> 12370.69 | F15: =SUMIFS('04_Base_Despesas'!$D$4:$D$219, '04_Base_Despesas'!$A$4:$A$219, F$5, '04_Base_Despesas'!$B$4:$B$219, "marketing") -> 17102.54 | G15: =SUMIFS('04_Base_Despesas'!$D$4:$D$219, '04_Base_Despesas'!$A$4:$A$219, G$5, '04_Base_Despesas'!$B$4:$B$219, "marketing") -> 17727.79 | H15: =SUMIFS('04_Base_Despesas'!$D$4:$D$219, '04_Base_Despesas'!$A$4:$A$219, H$5, '04_Base_Despesas'!$B$4:$B$219, "marketing") -> 9948.49 | I15: =SUMIFS('04_Base_Despesas'!$D$4:$D$219, '04_Base_Despesas'!$A$4:$A$219, I$5, '04_Base_Despesas'!$B$4:$B$219, "marketing") -> 12849.46 | ... Y15: =SUMIFS('04_Base_Despesas'!$D$4:$D$219, '04_Base_Despesas'!$A$4:$A$219, Y$5, '04_Base_Despesas'!$B$4:$B$219, "marketing") -> 14130.97 | Z15: =SUM(B15:Y15) -> 350191.86
A16: (−) Logística | B16: =SUMIFS('04_Base_Despesas'!$D$4:$D$219, '04_Base_Despesas'!$A$4:$A$219, B$5, '04_Base_Despesas'!$B$4:$B$219, "logistica") -> 8993.95 | C16: =SUMIFS('04_Base_Despesas'!$D$4:$D$219, '04_Base_Despesas'!$A$4:$A$219, C$5, '04_Base_Despesas'!$B$4:$B$219, "logistica") -> 9160.58 | D16: =SUMIFS('04_Base_Despesas'!$D$4:$D$219, '04_Base_Despesas'!$A$4:$A$219, D$5, '04_Base_Despesas'!$B$4:$B$219, "logistica") -> 9764.07 | E16: =SUMIFS('04_Base_Despesas'!$D$4:$D$219, '04_Base_Despesas'!$A$4:$A$219, E$5, '04_Base_Despesas'!$B$4:$B$219, "logistica") -> 10858.12 | F16: =SUMIFS('04_Base_Despesas'!$D$4:$D$219, '04_Base_Despesas'!$A$4:$A$219, F$5, '04_Base_Despesas'!$B$4:$B$219, "logistica") -> 9866.92 | G16: =SUMIFS('04_Base_Despesas'!$D$4:$D$219, '04_Base_Despesas'!$A$4:$A$219, G$5, '04_Base_Despesas'!$B$4:$B$219, "logistica") -> 9425.93 | H16: =SUMIFS('04_Base_Despesas'!$D$4:$D$219, '04_Base_Despesas'!$A$4:$A$219, H$5, '04_Base_Despesas'!$B$4:$B$219, "logistica") -> 10739.52 | I16: =SUMIFS('04_Base_Despesas'!$D$4:$D$219, '04_Base_Despesas'!$A$4:$A$219, I$5, '04_Base_Despesas'!$B$4:$B$219, "logistica") -> 10757.29 | ... Y16: =SUMIFS('04_Base_Despesas'!$D$4:$D$219, '04_Base_Despesas'!$A$4:$A$219, Y$5, '04_Base_Despesas'!$B$4:$B$219, "logistica") -> 9303.17 | Z16: =SUM(B16:Y16) -> 238776.73
A17: (−) Tecnologia | B17: =SUMIFS('04_Base_Despesas'!$D$4:$D$219, '04_Base_Despesas'!$A$4:$A$219, B$5, '04_Base_Despesas'!$B$4:$B$219, "tecnologia") -> 6715.05 | C17: =SUMIFS('04_Base_Despesas'!$D$4:$D$219, '04_Base_Despesas'!$A$4:$A$219, C$5, '04_Base_Despesas'!$B$4:$B$219, "tecnologia") -> 6617.13 | D17: =SUMIFS('04_Base_Despesas'!$D$4:$D$219, '04_Base_Despesas'!$A$4:$A$219, D$5, '04_Base_Despesas'!$B$4:$B$219, "tecnologia") -> 6653.07 | E17: =SUMIFS('04_Base_Despesas'!$D$4:$D$219, '04_Base_Despesas'!$A$4:$A$219, E$5, '04_Base_Despesas'!$B$4:$B$219, "tecnologia") -> 6588.75 | F17: =SUMIFS('04_Base_Despesas'!$D$4:$D$219, '04_Base_Despesas'!$A$4:$A$219, F$5, '04_Base_Despesas'!$B$4:$B$219, "tecnologia") -> 6590.3 | G17: =SUMIFS('04_Base_Despesas'!$D$4:$D$219, '04_Base_Despesas'!$A$4:$A$219, G$5, '04_Base_Despesas'!$B$4:$B$219, "tecnologia") -> 6700.43 | H17: =SUMIFS('04_Base_Despesas'!$D$4:$D$219, '04_Base_Despesas'!$A$4:$A$219, H$5, '04_Base_Despesas'!$B$4:$B$219, "tecnologia") -> 6624.29 | I17: =SUMIFS('04_Base_Despesas'!$D$4:$D$219, '04_Base_Despesas'!$A$4:$A$219, I$5, '04_Base_Despesas'!$B$4:$B$219, "tecnologia") -> 6794.75 | ... Y17: =SUMIFS('04_Base_Despesas'!$D$4:$D$219, '04_Base_Despesas'!$A$4:$A$219, Y$5, '04_Base_Despesas'!$B$4:$B$219, "tecnologia") -> 0 | Z17: =SUM(B17:Y17) -> 153669.48
A18: (−) Administrativo | B18: =SUMIFS('04_Base_Despesas'!$D$4:$D$219, '04_Base_Despesas'!$A$4:$A$219, B$5, '04_Base_Despesas'!$B$4:$B$219, "administrativo") -> 4109.09 | C18: =SUMIFS('04_Base_Despesas'!$D$4:$D$219, '04_Base_Despesas'!$A$4:$A$219, C$5, '04_Base_Despesas'!$B$4:$B$219, "administrativo") -> 2500 | D18: =SUMIFS('04_Base_Despesas'!$D$4:$D$219, '04_Base_Despesas'!$A$4:$A$219, D$5, '04_Base_Despesas'!$B$4:$B$219, "administrativo") -> 2500 | E18: =SUMIFS('04_Base_Despesas'!$D$4:$D$219, '04_Base_Despesas'!$A$4:$A$219, E$5, '04_Base_Despesas'!$B$4:$B$219, "administrativo") -> 4557.28 | F18: =SUMIFS('04_Base_Despesas'!$D$4:$D$219, '04_Base_Despesas'!$A$4:$A$219, F$5, '04_Base_Despesas'!$B$4:$B$219, "administrativo") -> 2500 | G18: =SUMIFS('04_Base_Despesas'!$D$4:$D$219, '04_Base_Despesas'!$A$4:$A$219, G$5, '04_Base_Despesas'!$B$4:$B$219, "administrativo") -> 2500 | H18: =SUMIFS('04_Base_Despesas'!$D$4:$D$219, '04_Base_Despesas'!$A$4:$A$219, H$5, '04_Base_Despesas'!$B$4:$B$219, "administrativo") -> 4252.75 | I18: =SUMIFS('04_Base_Despesas'!$D$4:$D$219, '04_Base_Despesas'!$A$4:$A$219, I$5, '04_Base_Despesas'!$B$4:$B$219, "administrativo") -> 2500 | ... Y18: =SUMIFS('04_Base_Despesas'!$D$4:$D$219, '04_Base_Despesas'!$A$4:$A$219, Y$5, '04_Base_Despesas'!$B$4:$B$219, "administrativo") -> 2500 | Z18: =SUM(B18:Y18) -> 75132.22
A19: (−) Outros | B19: =SUMIFS('04_Base_Despesas'!$D$4:$D$219, '04_Base_Despesas'!$A$4:$A$219, B$5, '04_Base_Despesas'!$B$4:$B$219, "outros") -> 791.43 | C19: =SUMIFS('04_Base_Despesas'!$D$4:$D$219, '04_Base_Despesas'!$A$4:$A$219, C$5, '04_Base_Despesas'!$B$4:$B$219, "outros") -> 878.67 | D19: =SUMIFS('04_Base_Despesas'!$D$4:$D$219, '04_Base_Despesas'!$A$4:$A$219, D$5, '04_Base_Despesas'!$B$4:$B$219, "outros") -> 864.81 | E19: =SUMIFS('04_Base_Despesas'!$D$4:$D$219, '04_Base_Despesas'!$A$4:$A$219, E$5, '04_Base_Despesas'!$B$4:$B$219, "outros") -> 688.55 | F19: =SUMIFS('04_Base_Despesas'!$D$4:$D$219, '04_Base_Despesas'!$A$4:$A$219, F$5, '04_Base_Despesas'!$B$4:$B$219, "outros") -> 773.72 | G19: =SUMIFS('04_Base_Despesas'!$D$4:$D$219, '04_Base_Despesas'!$A$4:$A$219, G$5, '04_Base_Despesas'!$B$4:$B$219, "outros") -> 770.82 | H19: =SUMIFS('04_Base_Despesas'!$D$4:$D$219, '04_Base_Despesas'!$A$4:$A$219, H$5, '04_Base_Despesas'!$B$4:$B$219, "outros") -> 984.56 | I19: =SUMIFS('04_Base_Despesas'!$D$4:$D$219, '04_Base_Despesas'!$A$4:$A$219, I$5, '04_Base_Despesas'!$B$4:$B$219, "outros") -> 873.81 | ... Y19: =SUMIFS('04_Base_Despesas'!$D$4:$D$219, '04_Base_Despesas'!$A$4:$A$219, Y$5, '04_Base_Despesas'!$B$4:$B$219, "outros") -> 648.47 | Z19: =SUM(B19:Y19) -> 20427.8
A20: Total Despesas Operac. | B20: =B13+B14+B15+B16+B17+B18+B19 -> 98608.23 | C20: =C13+C14+C15+C16+C17+C18+C19 -> 92928.73 | D20: =D13+D14+D15+D16+D17+D18+D19 -> 90397.78 | E20: =E13+E14+E15+E16+E17+E18+E19 -> 94036.22 | F20: =F13+F14+F15+F16+F17+F18+F19 -> 98318.36 | G20: =G13+G14+G15+G16+G17+G18+G19 -> 97207.82 | H20: =H13+H14+H15+H16+H17+H18+H19 -> 93932.6 | I20: =I13+I14+I15+I16+I17+I18+I19 -> 95179.81 | ... Y20: =Y13+Y14+Y15+Y16+Y17+Y18+Y19 -> 87191.94 | Z20: =SUM(B20:Y20) -> 2298567.7
A21: EBITDA | B21: =B11-B20 -> -29797.17 | C21: =C11-C20 -> -37170.33 | D21: =D11-D20 -> -21865.99 | E21: =E11-E20 -> -30014.25 | F21: =F11-F20 -> -7727.97 | G21: =G11-G20 -> -21166.51 | H21: =H11-H20 -> -35000.82 | I21: =I11-I20 -> -36529.78 | ... Y21: =Y11-Y20 -> 1974.42 | Z21: =SUM(B21:Y21) -> -502504.1
A22: % Margem EBITDA | B22: =IFERROR(B21/B9,0) -> -0.19861847 | C22: =IFERROR(C21/C9,0) -> -0.29805054 | D22: =IFERROR(D21/D9,0) -> -0.14375892 | E22: =IFERROR(E21/E9,0) -> -0.21466939 | F22: =IFERROR(F21/F9,0) -> -0.039631581 | G22: =IFERROR(G21/G9,0) -> -0.1247126 | H22: =IFERROR(H21/H9,0) -> -0.27088588 | I22: =IFERROR(I21/I9,0) -> -0.28329801 | ... Y22: =IFERROR(Y21/Y9,0) -> 0.010163005 | Z22: =IFERROR($Z$21/$Z$9,0) -> -0.12641442
A23: (−) Depreciação | B23: =SUMIFS('04_Base_Despesas'!$D$4:$D$219, '04_Base_Despesas'!$A$4:$A$219, B$5, '04_Base_Despesas'!$B$4:$B$219, "depreciacao") -> 2199.99 | C23: =SUMIFS('04_Base_Despesas'!$D$4:$D$219, '04_Base_Despesas'!$A$4:$A$219, C$5, '04_Base_Despesas'!$B$4:$B$219, "depreciacao") -> 2200 | D23: =SUMIFS('04_Base_Despesas'!$D$4:$D$219, '04_Base_Despesas'!$A$4:$A$219, D$5, '04_Base_Despesas'!$B$4:$B$219, "depreciacao") -> 2199.99 | E23: =SUMIFS('04_Base_Despesas'!$D$4:$D$219, '04_Base_Despesas'!$A$4:$A$219, E$5, '04_Base_Despesas'!$B$4:$B$219, "depreciacao") -> 2199.99 | F23: =SUMIFS('04_Base_Despesas'!$D$4:$D$219, '04_Base_Despesas'!$A$4:$A$219, F$5, '04_Base_Despesas'!$B$4:$B$219, "depreciacao") -> 2199.99 | G23: =SUMIFS('04_Base_Despesas'!$D$4:$D$219, '04_Base_Despesas'!$A$4:$A$219, G$5, '04_Base_Despesas'!$B$4:$B$219, "depreciacao") -> 2199.99 | H23: =SUMIFS('04_Base_Despesas'!$D$4:$D$219, '04_Base_Despesas'!$A$4:$A$219, H$5, '04_Base_Despesas'!$B$4:$B$219, "depreciacao") -> 2199.99 | I23: =SUMIFS('04_Base_Despesas'!$D$4:$D$219, '04_Base_Despesas'!$A$4:$A$219, I$5, '04_Base_Despesas'!$B$4:$B$219, "depreciacao") -> 2200 | ... Y23: =SUMIFS('04_Base_Despesas'!$D$4:$D$219, '04_Base_Despesas'!$A$4:$A$219, Y$5, '04_Base_Despesas'!$B$4:$B$219, "depreciacao") -> 2200 | Z23: =SUM(B23:Y23) -> 52799.91
A24: EBIT | B24: =B21-B23 -> -31997.16 | C24: =C21-C23 -> -39370.33 | D24: =D21-D23 -> -24065.98 | E24: =E21-E23 -> -32214.24 | F24: =F21-F23 -> -9927.96 | G24: =G21-G23 -> -23366.5 | H24: =H21-H23 -> -37200.81 | I24: =I21-I23 -> -38729.78 | ... Y24: =Y21-Y23 -> -225.58 | Z24: =SUM(B24:Y24) -> -555304.01
A25: (−) Despesas Financeiras | B25: =SUMIFS('04_Base_Despesas'!$D$4:$D$219, '04_Base_Despesas'!$A$4:$A$219, B$5, '04_Base_Despesas'!$B$4:$B$219, "financeiro") -> 1365.44 | C25: =SUMIFS('04_Base_Despesas'!$D$4:$D$219, '04_Base_Despesas'!$A$4:$A$219, C$5, '04_Base_Despesas'!$B$4:$B$219, "financeiro") -> 1351.57 | D25: =SUMIFS('04_Base_Despesas'!$D$4:$D$219, '04_Base_Despesas'!$A$4:$A$219, D$5, '04_Base_Despesas'!$B$4:$B$219, "financeiro") -> 1345.81 | E25: =SUMIFS('04_Base_Despesas'!$D$4:$D$219, '04_Base_Despesas'!$A$4:$A$219, E$5, '04_Base_Despesas'!$B$4:$B$219, "financeiro") -> 1298.1 | F25: =SUMIFS('04_Base_Despesas'!$D$4:$D$219, '04_Base_Despesas'!$A$4:$A$219, F$5, '04_Base_Despesas'!$B$4:$B$219, "financeiro") -> 1353.03 | G25: =SUMIFS('04_Base_Despesas'!$D$4:$D$219, '04_Base_Despesas'!$A$4:$A$219, G$5, '04_Base_Despesas'!$B$4:$B$219, "financeiro") -> 1278.47 | H25: =SUMIFS('04_Base_Despesas'!$D$4:$D$219, '04_Base_Despesas'!$A$4:$A$219, H$5, '04_Base_Despesas'!$B$4:$B$219, "financeiro") -> 5445.99 | I25: =SUMIFS('04_Base_Despesas'!$D$4:$D$219, '04_Base_Despesas'!$A$4:$A$219, I$5, '04_Base_Despesas'!$B$4:$B$219, "financeiro") -> 1313.68 | ... Y25: =SUMIFS('04_Base_Despesas'!$D$4:$D$219, '04_Base_Despesas'!$A$4:$A$219, Y$5, '04_Base_Despesas'!$B$4:$B$219, "financeiro") -> 1383.86 | Z25: =SUM(B25:Y25) -> 35628.56
A26: Resultado Operacional | B26: =B24-B25 -> -33362.6 | C26: =C24-C25 -> -40721.9 | D26: =D24-D25 -> -25411.79 | E26: =E24-E25 -> -33512.34 | F26: =F24-F25 -> -11280.99 | G26: =G24-G25 -> -24644.97 | H26: =H24-H25 -> -42646.8 | I26: =I24-I25 -> -40043.46 | ... Y26: =Y24-Y25 -> -1609.44 | Z26: =SUM(B26:Y26) -> -590932.57
A27: % Margem Operacional | B27: =IFERROR(B26/B9,0) -> -0.22238449 | C27: =IFERROR(C26/C9,0) -> -0.32652883 | D27: =IFERROR(D26/D9,0) -> -0.16707094 | E27: =IFERROR(E26/E9,0) -> -0.2396886 | F27: =IFERROR(F26/F9,0) -> -0.05785264 | G27: =IFERROR(G26/G9,0) -> -0.14520761 | H27: =IFERROR(H26/H9,0) -> -0.33006129 | I27: =IFERROR(I26/I9,0) -> -0.31054752 | ... Y27: =IFERROR(Y26/Y9,0) -> -0.0082843298 | Z27: =IFERROR($Z$26/$Z$9,0) -> -0.14866027

Sheet 07_DRE_por_Canal
A1: 07 — DRE POR CANAL
A2: DREs replicadas por canal. Despesas operacionais e financeiras são rateadas pelo share de receita líquida do canal no mês.
A4: Rateio: as despesas centrais (pessoal, aluguel, marketing, logística, etc.) são distribuídas pelo canal proporcionalmente à sua receita líquida no mês. Linhas de receita, devoluções, comissões, CMV e margem de contribuição são alocação direta por canal.
A6: Canal: E-commerce
A7: Item | B7: 2023-01 | C7: 2023-02 | D7: 2023-03 | E7: 2023-04 | F7: 2023-05 | G7: 2023-06 | H7: 2023-07 | I7: 2023-08 | J7: 2023-09 | K7: 2023-10 | L7: 2023-11 | M7: 2023-12 | N7: 2024-01 | O7: 2024-02 | P7: 2024-03 | Q7: 2024-04 | R7: 2024-05 | S7: 2024-06 | T7: 2024-07 | U7: 2024-08 | V7: 2024-09 | W7: 2024-10 | X7: 2024-11 | Y7: 2024-12 | Z7: Total 24m
A8: Receita Bruta | B8: =SUMIFS('03_Base_Vendas'!$F$4:$F$387, '03_Base_Vendas'!$A$4:$A$387, B$7, '03_Base_Vendas'!$B$4:$B$387, "ecommerce") -> 68636.19 | C8: =SUMIFS('03_Base_Vendas'!$F$4:$F$387, '03_Base_Vendas'!$A$4:$A$387, C$7, '03_Base_Vendas'!$B$4:$B$387, "ecommerce") -> 66148.95 | D8: =SUMIFS('03_Base_Vendas'!$F$4:$F$387, '03_Base_Vendas'!$A$4:$A$387, D$7, '03_Base_Vendas'!$B$4:$B$387, "ecommerce") -> 70357.55 | E8: =SUMIFS('03_Base_Vendas'!$F$4:$F$387, '03_Base_Vendas'!$A$4:$A$387, E$7, '03_Base_Vendas'!$B$4:$B$387, "ecommerce") -> 65336.91 | F8: =SUMIFS('03_Base_Vendas'!$F$4:$F$387, '03_Base_Vendas'!$A$4:$A$387, F$7, '03_Base_Vendas'!$B$4:$B$387, "ecommerce") -> 101416.68 | G8: =SUMIFS('03_Base_Vendas'!$F$4:$F$387, '03_Base_Vendas'!$A$4:$A$387, G$7, '03_Base_Vendas'!$B$4:$B$387, "ecommerce") -> 87766.93 | H8: =SUMIFS('03_Base_Vendas'!$F$4:$F$387, '03_Base_Vendas'!$A$4:$A$387, H$7, '03_Base_Vendas'!$B$4:$B$387, "ecommerce") -> 66646.31 | I8: =SUMIFS('03_Base_Vendas'!$F$4:$F$387, '03_Base_Vendas'!$A$4:$A$387, I$7, '03_Base_Vendas'!$B$4:$B$387, "ecommerce") -> 64204.01 | ... Y8: =SUMIFS('03_Base_Vendas'!$F$4:$F$387, '03_Base_Vendas'!$A$4:$A$387, Y$7, '03_Base_Vendas'!$B$4:$B$387, "ecommerce") -> 105016.31 | Z8: =SUM(B8:Y8) -> 1943188.9
A9: (−) Devoluções | B9: =SUMIFS('03_Base_Vendas'!$G$4:$G$387, '03_Base_Vendas'!$A$4:$A$387, B$7, '03_Base_Vendas'!$B$4:$B$387, "ecommerce") -> 1942.53 | C9: =SUMIFS('03_Base_Vendas'!$G$4:$G$387, '03_Base_Vendas'!$A$4:$A$387, C$7, '03_Base_Vendas'!$B$4:$B$387, "ecommerce") -> 3660.31 | D9: =SUMIFS('03_Base_Vendas'!$G$4:$G$387, '03_Base_Vendas'!$A$4:$A$387, D$7, '03_Base_Vendas'!$B$4:$B$387, "ecommerce") -> 2128.42 | E9: =SUMIFS('03_Base_Vendas'!$G$4:$G$387, '03_Base_Vendas'!$A$4:$A$387, E$7, '03_Base_Vendas'!$B$4:$B$387, "ecommerce") -> 2640.31 | F9: =SUMIFS('03_Base_Vendas'!$G$4:$G$387, '03_Base_Vendas'!$A$4:$A$387, F$7, '03_Base_Vendas'!$B$4:$B$387, "ecommerce") -> 2478.76 | G9: =SUMIFS('03_Base_Vendas'!$G$4:$G$387, '03_Base_Vendas'!$A$4:$A$387, G$7, '03_Base_Vendas'!$B$4:$B$387, "ecommerce") -> 3237.31 | H9: =SUMIFS('03_Base_Vendas'!$G$4:$G$387, '03_Base_Vendas'!$A$4:$A$387, H$7, '03_Base_Vendas'!$B$4:$B$387, "ecommerce") -> 790.33 | I9: =SUMIFS('03_Base_Vendas'!$G$4:$G$387, '03_Base_Vendas'!$A$4:$A$387, I$7, '03_Base_Vendas'!$B$4:$B$387, "ecommerce") -> 2014.64 | ... Y9: =SUMIFS('03_Base_Vendas'!$G$4:$G$387, '03_Base_Vendas'!$A$4:$A$387, Y$7, '03_Base_Vendas'!$B$4:$B$387, "ecommerce") -> 1827.61 | Z9: =SUM(B9:Y9) -> 57894.53
A10: (−) Comissões de canal | B10: =SUMIFS('03_Base_Vendas'!$H$4:$H$387, '03_Base_Vendas'!$A$4:$A$387, B$7, '03_Base_Vendas'!$B$4:$B$387, "ecommerce") -> 2806.55 | C10: =SUMIFS('03_Base_Vendas'!$H$4:$H$387, '03_Base_Vendas'!$A$4:$A$387, C$7, '03_Base_Vendas'!$B$4:$B$387, "ecommerce") -> 2615.42 | D10: =SUMIFS('03_Base_Vendas'!$H$4:$H$387, '03_Base_Vendas'!$A$4:$A$387, D$7, '03_Base_Vendas'!$B$4:$B$387, "ecommerce") -> 2846.6 | E10: =SUMIFS('03_Base_Vendas'!$H$4:$H$387, '03_Base_Vendas'!$A$4:$A$387, E$7, '03_Base_Vendas'!$B$4:$B$387, "ecommerce") -> 2656.28 | F10: =SUMIFS('03_Base_Vendas'!$H$4:$H$387, '03_Base_Vendas'!$A$4:$A$387, F$7, '03_Base_Vendas'!$B$4:$B$387, "ecommerce") -> 3975.57 | G10: =SUMIFS('03_Base_Vendas'!$H$4:$H$387, '03_Base_Vendas'!$A$4:$A$387, G$7, '03_Base_Vendas'!$B$4:$B$387, "ecommerce") -> 3480.01 | H10: =SUMIFS('03_Base_Vendas'!$H$4:$H$387, '03_Base_Vendas'!$A$4:$A$387, H$7, '03_Base_Vendas'!$B$4:$B$387, "ecommerce") -> 2639.68 | I10: =SUMIFS('03_Base_Vendas'!$H$4:$H$387, '03_Base_Vendas'!$A$4:$A$387, I$7, '03_Base_Vendas'!$B$4:$B$387, "ecommerce") -> 2523.04 | ... Y10: =SUMIFS('03_Base_Vendas'!$H$4:$H$387, '03_Base_Vendas'!$A$4:$A$387, Y$7, '03_Base_Vendas'!$B$4:$B$387, "ecommerce") -> 4244.96 | Z10: =SUM(B10:Y10) -> 77414.93
A11: Receita Líquida | B11: =B8-B9-B10 -> 63887.11 | C11: =C8-C9-C10 -> 59873.22 | D11: =D8-D9-D10 -> 65382.53 | E11: =E8-E9-E10 -> 60040.32 | F11: =F8-F9-F10 -> 94962.35 | G11: =G8-G9-G10 -> 81049.61 | H11: =H8-H9-H10 -> 63216.3 | I11: =I8-I9-I10 -> 59666.33 | ... Y11: =Y8-Y9-Y10 -> 98943.74 | Z11: =SUM(B11:Y11) -> 1807879.5
A12: (−) CMV | B12: =SUMIFS('03_Base_Vendas'!$J$4:$J$387, '03_Base_Vendas'!$A$4:$A$387, B$7, '03_Base_Vendas'!$B$4:$B$387, "ecommerce") -> 32724.81 | C12: =SUMIFS('03_Base_Vendas'!$J$4:$J$387, '03_Base_Vendas'!$A$4:$A$387, C$7, '03_Base_Vendas'!$B$4:$B$387, "ecommerce") -> 31609.47 | D12: =SUMIFS('03_Base_Vendas'!$J$4:$J$387, '03_Base_Vendas'!$A$4:$A$387, D$7, '03_Base_Vendas'!$B$4:$B$387, "ecommerce") -> 34083.99 | E12: =SUMIFS('03_Base_Vendas'!$J$4:$J$387, '03_Base_Vendas'!$A$4:$A$387, E$7, '03_Base_Vendas'!$B$4:$B$387, "ecommerce") -> 30620.35 | F12: =SUMIFS('03_Base_Vendas'!$J$4:$J$387, '03_Base_Vendas'!$A$4:$A$387, F$7, '03_Base_Vendas'!$B$4:$B$387, "ecommerce") -> 48888.53 | G12: =SUMIFS('03_Base_Vendas'!$J$4:$J$387, '03_Base_Vendas'!$A$4:$A$387, G$7, '03_Base_Vendas'!$B$4:$B$387, "ecommerce") -> 43155.15 | H12: =SUMIFS('03_Base_Vendas'!$J$4:$J$387, '03_Base_Vendas'!$A$4:$A$387, H$7, '03_Base_Vendas'!$B$4:$B$387, "ecommerce") -> 32083.03 | I12: =SUMIFS('03_Base_Vendas'!$J$4:$J$387, '03_Base_Vendas'!$A$4:$A$387, I$7, '03_Base_Vendas'!$B$4:$B$387, "ecommerce") -> 30738 | ... Y12: =SUMIFS('03_Base_Vendas'!$J$4:$J$387, '03_Base_Vendas'!$A$4:$A$387, Y$7, '03_Base_Vendas'!$B$4:$B$387, "ecommerce") -> 50354.61 | Z12: =SUM(B12:Y12) -> 931100.49
A13: Margem de Contribuição | B13: =B11-B12 -> 31162.3 | C13: =C11-C12 -> 28263.75 | D13: =D11-D12 -> 31298.54 | E13: =E11-E12 -> 29419.97 | F13: =F11-F12 -> 46073.82 | G13: =G11-G12 -> 37894.46 | H13: =H11-H12 -> 31133.27 | I13: =I11-I12 -> 28928.33 | ... Y13: =Y11-Y12 -> 48589.13 | Z13: =SUM(B13:Y13) -> 876778.97
A14: % Margem de Contribuição | B14: =IFERROR(B13/B11,0) -> 0.48777132 | C14: =IFERROR(C13/C11,0) -> 0.47205996 | D14: =IFERROR(D13/D11,0) -> 0.47869882 | E14: =IFERROR(E13/E11,0) -> 0.49000355 | F14: =IFERROR(F13/F11,0) -> 0.48517986 | G14: =IFERROR(G13/G11,0) -> 0.46754648 | H14: =IFERROR(H13/H11,0) -> 0.49248801 | I14: =IFERROR(I13/I11,0) -> 0.48483508 | ... Y14: =IFERROR(Y13/Y11,0) -> 0.49107836 | Z14: =IFERROR($Z$13/$Z$11,0) -> 0.48497645
A15: (−) Pessoal | B15: =(SUMIFS('04_Base_Despesas'!$D$4:$D$219, '04_Base_Despesas'!$A$4:$A$219, B$7, '04_Base_Despesas'!$B$4:$B$219, "pessoal"))*(IFERROR(SUMIFS('03_Base_Vendas'!$I$4:$I$387, '03_Base_Vendas'!$A$4:$A$387, B$7, '03_Base_Vendas'!$B$4:$B$387, "ecommerce")/SUMIFS('03_Base_Vendas'!$I$4:$I$387, '03_Base_Vendas'!$A$4:$A$387, B$7),0)) -> 21570.346 | C15: =(SUMIFS('04_Base_Despesas'!$D$4:$D$219, '04_Base_Despesas'!$A$4:$A$219, C$7, '04_Base_Despesas'!$B$4:$B$219, "pessoal"))*(IFERROR(SUMIFS('03_Base_Vendas'!$I$4:$I$387, '03_Base_Vendas'!$A$4:$A$387, C$7, '03_Base_Vendas'!$B$4:$B$387, "ecommerce")/SUMIFS('03_Base_Vendas'!$I$4:$I$387, '03_Base_Vendas'!$A$4:$A$387, C$7),0)) -> 25024.468 | D15: =(SUMIFS('04_Base_Despesas'!$D$4:$D$219, '04_Base_Despesas'!$A$4:$A$219, D$7, '04_Base_Despesas'!$B$4:$B$219, "pessoal"))*(IFERROR(SUMIFS('03_Base_Vendas'!$I$4:$I$387, '03_Base_Vendas'!$A$4:$A$387, D$7, '03_Base_Vendas'!$B$4:$B$387, "ecommerce")/SUMIFS('03_Base_Vendas'!$I$4:$I$387, '03_Base_Vendas'!$A$4:$A$387, D$7),0)) -> 21546.642 | E15: =(SUMIFS('04_Base_Despesas'!$D$4:$D$219, '04_Base_Despesas'!$A$4:$A$219, E$7, '04_Base_Despesas'!$B$4:$B$219, "pessoal"))*(IFERROR(SUMIFS('03_Base_Vendas'!$I$4:$I$387, '03_Base_Vendas'!$A$4:$A$387, E$7, '03_Base_Vendas'!$B$4:$B$387, "ecommerce")/SUMIFS('03_Base_Vendas'!$I$4:$I$387, '03_Base_Vendas'!$A$4:$A$387, E$7),0)) -> 21244.787 | F15: =(SUMIFS('04_Base_Despesas'!$D$4:$D$219, '04_Base_Despesas'!$A$4:$A$219, F$7, '04_Base_Despesas'!$B$4:$B$219, "pessoal"))*(IFERROR(SUMIFS('03_Base_Vendas'!$I$4:$I$387, '03_Base_Vendas'!$A$4:$A$387, F$7, '03_Base_Vendas'!$B$4:$B$387, "ecommerce")/SUMIFS('03_Base_Vendas'!$I$4:$I$387, '03_Base_Vendas'!$A$4:$A$387, F$7),0)) -> 25316.547 | G15: =(SUMIFS('04_Base_Despesas'!$D$4:$D$219, '04_Base_Despesas'!$A$4:$A$219, G$7, '04_Base_Despesas'!$B$4:$B$219, "pessoal"))*(IFERROR(SUMIFS('03_Base_Vendas'!$I$4:$I$387, '03_Base_Vendas'!$A$4:$A$387, G$7, '03_Base_Vendas'!$B$4:$B$387, "ecommerce")/SUMIFS('03_Base_Vendas'!$I$4:$I$387, '03_Base_Vendas'!$A$4:$A$387, G$7),0)) -> 24155.46 | H15: =(SUMIFS('04_Base_Despesas'!$D$4:$D$219, '04_Base_Despesas'!$A$4:$A$219, H$7, '04_Base_Despesas'!$B$4:$B$219, "pessoal"))*(IFERROR(SUMIFS('03_Base_Vendas'!$I$4:$I$387, '03_Base_Vendas'!$A$4:$A$387, H$7, '03_Base_Vendas'!$B$4:$B$387, "ecommerce")/SUMIFS('03_Base_Vendas'!$I$4:$I$387, '03_Base_Vendas'!$A$4:$A$387, H$7),0)) -> 25384.126 | I15: =(SUMIFS('04_Base_Despesas'!$D$4:$D$219, '04_Base_Despesas'!$A$4:$A$219, I$7, '04_Base_Despesas'!$B$4:$B$219, "pessoal"))*(IFERROR(SUMIFS('03_Base_Vendas'!$I$4:$I$387, '03_Base_Vendas'!$A$4:$A$387, I$7, '03_Base_Vendas'!$B$4:$B$387, "ecommerce")/SUMIFS('03_Base_Vendas'!$I$4:$I$387, '03_Base_Vendas'!$A$4:$A$387, I$7),0)) -> 24017.666 | ... Y15: =(SUMIFS('04_Base_Despesas'!$D$4:$D$219, '04_Base_Despesas'!$A$4:$A$219, Y$7, '04_Base_Despesas'!$B$4:$B$219, "pessoal"))*(IFERROR(SUMIFS('03_Base_Vendas'!$I$4:$I$387, '03_Base_Vendas'!$A$4:$A$387, Y$7, '03_Base_Vendas'!$B$4:$B$387, "ecommerce")/SUMIFS('03_Base_Vendas'!$I$4:$I$387, '03_Base_Vendas'!$A$4:$A$387, Y$7),0)) -> 26029.811 | Z15: =SUM(B15:Y15) -> 561117.29
A16: (−) Aluguel | B16: =(SUMIFS('04_Base_Despesas'!$D$4:$D$219, '04_Base_Despesas'!$A$4:$A$219, B$7, '04_Base_Despesas'!$B$4:$B$219, "aluguel"))*(IFERROR(SUMIFS('03_Base_Vendas'!$I$4:$I$387, '03_Base_Vendas'!$A$4:$A$387, B$7, '03_Base_Vendas'!$B$4:$B$387, "ecommerce")/SUMIFS('03_Base_Vendas'!$I$4:$I$387, '03_Base_Vendas'!$A$4:$A$387, B$7),0)) -> 4045.5905 | C16: =(SUMIFS('04_Base_Despesas'!$D$4:$D$219, '04_Base_Despesas'!$A$4:$A$219, C$7, '04_Base_Despesas'!$B$4:$B$219, "aluguel"))*(IFERROR(SUMIFS('03_Base_Vendas'!$I$4:$I$387, '03_Base_Vendas'!$A$4:$A$387, C$7, '03_Base_Vendas'!$B$4:$B$387, "ecommerce")/SUMIFS('03_Base_Vendas'!$I$4:$I$387, '03_Base_Vendas'!$A$4:$A$387, C$7),0)) -> 4560.8913 | D16: =(SUMIFS('04_Base_Despesas'!$D$4:$D$219, '04_Base_Despesas'!$A$4:$A$219, D$7, '04_Base_Despesas'!$B$4:$B$219, "aluguel"))*(IFERROR(SUMIFS('03_Base_Vendas'!$I$4:$I$387, '03_Base_Vendas'!$A$4:$A$387, D$7, '03_Base_Vendas'!$B$4:$B$387, "ecommerce")/SUMIFS('03_Base_Vendas'!$I$4:$I$387, '03_Base_Vendas'!$A$4:$A$387, D$7),0)) -> 4083.6731 | E16: =(SUMIFS('04_Base_Despesas'!$D$4:$D$219, '04_Base_Despesas'!$A$4:$A$219, E$7, '04_Base_Despesas'!$B$4:$B$219, "aluguel"))*(IFERROR(SUMIFS('03_Base_Vendas'!$I$4:$I$387, '03_Base_Vendas'!$A$4:$A$387, E$7, '03_Base_Vendas'!$B$4:$B$387, "ecommerce")/SUMIFS('03_Base_Vendas'!$I$4:$I$387, '03_Base_Vendas'!$A$4:$A$387, E$7),0)) -> 4079.5216 | F16: =(SUMIFS('04_Base_Despesas'!$D$4:$D$219, '04_Base_Despesas'!$A$4:$A$219, F$7, '04_Base_Despesas'!$B$4:$B$219, "aluguel"))*(IFERROR(SUMIFS('03_Base_Vendas'!$I$4:$I$387, '03_Base_Vendas'!$A$4:$A$387, F$7, '03_Base_Vendas'!$B$4:$B$387, "ecommerce")/SUMIFS('03_Base_Vendas'!$I$4:$I$387, '03_Base_Vendas'!$A$4:$A$387, F$7),0)) -> 4626.4836 | G16: =(SUMIFS('04_Base_Despesas'!$D$4:$D$219, '04_Base_Despesas'!$A$4:$A$219, G$7, '04_Base_Despesas'!$B$4:$B$219, "aluguel"))*(IFERROR(SUMIFS('03_Base_Vendas'!$I$4:$I$387, '03_Base_Vendas'!$A$4:$A$387, G$7, '03_Base_Vendas'!$B$4:$B$387, "ecommerce")/SUMIFS('03_Base_Vendas'!$I$4:$I$387, '03_Base_Vendas'!$A$4:$A$387, G$7),0)) -> 4536.6537 | H16: =(SUMIFS('04_Base_Despesas'!$D$4:$D$219, '04_Base_Despesas'!$A$4:$A$219, H$7, '04_Base_Despesas'!$B$4:$B$219, "aluguel"))*(IFERROR(SUMIFS('03_Base_Vendas'!$I$4:$I$387, '03_Base_Vendas'!$A$4:$A$387, H$7, '03_Base_Vendas'!$B$4:$B$387, "ecommerce")/SUMIFS('03_Base_Vendas'!$I$4:$I$387, '03_Base_Vendas'!$A$4:$A$387, H$7),0)) -> 4647.9433 | I16: =(SUMIFS('04_Base_Despesas'!$D$4:$D$219, '04_Base_Despesas'!$A$4:$A$219, I$7, '04_Base_Despesas'!$B$4:$B$219, "aluguel"))*(IFERROR(SUMIFS('03_Base_Vendas'!$I$4:$I$387, '03_Base_Vendas'!$A$4:$A$387, I$7, '03_Base_Vendas'!$B$4:$B$387, "ecommerce")/SUMIFS('03_Base_Vendas'!$I$4:$I$387, '03_Base_Vendas'!$A$4:$A$387, I$7),0)) -> 4395.9162 | ... Y16: =(SUMIFS('04_Base_Despesas'!$D$4:$D$219, '04_Base_Despesas'!$A$4:$A$219, Y$7, '04_Base_Despesas'!$B$4:$B$219, "aluguel"))*(IFERROR(SUMIFS('03_Base_Vendas'!$I$4:$I$387, '03_Base_Vendas'!$A$4:$A$387, Y$7, '03_Base_Vendas'!$B$4:$B$387, "ecommerce")/SUMIFS('03_Base_Vendas'!$I$4:$I$387, '03_Base_Vendas'!$A$4:$A$387, Y$7),0)) -> 4838.3243 | Z16: =SUM(B16:Y16) -> 103774.22
A17: (−) Marketing | B17: =(SUMIFS('04_Base_Despesas'!$D$4:$D$219, '04_Base_Despesas'!$A$4:$A$219, B$7, '04_Base_Despesas'!$B$4:$B$219, "marketing"))*(IFERROR(SUMIFS('03_Base_Vendas'!$I$4:$I$387, '03_Base_Vendas'!$A$4:$A$387, B$7, '03_Base_Vendas'!$B$4:$B$387, "ecommerce")/SUMIFS('03_Base_Vendas'!$I$4:$I$387, '03_Base_Vendas'!$A$4:$A$387, B$7),0)) -> 7599.9063 | C17: =(SUMIFS('04_Base_Despesas'!$D$4:$D$219, '04_Base_Despesas'!$A$4:$A$219, C$7, '04_Base_Despesas'!$B$4:$B$219, "marketing"))*(IFERROR(SUMIFS('03_Base_Vendas'!$I$4:$I$387, '03_Base_Vendas'!$A$4:$A$387, C$7, '03_Base_Vendas'!$B$4:$B$387, "ecommerce")/SUMIFS('03_Base_Vendas'!$I$4:$I$387, '03_Base_Vendas'!$A$4:$A$387, C$7),0)) -> 5832.2901 | D17: =(SUMIFS('04_Base_Despesas'!$D$4:$D$219, '04_Base_Despesas'!$A$4:$A$219, D$7, '04_Base_Despesas'!$B$4:$B$219, "marketing"))*(IFERROR(SUMIFS('03_Base_Vendas'!$I$4:$I$387, '03_Base_Vendas'!$A$4:$A$387, D$7, '03_Base_Vendas'!$B$4:$B$387, "ecommerce")/SUMIFS('03_Base_Vendas'!$I$4:$I$387, '03_Base_Vendas'!$A$4:$A$387, D$7),0)) -> 4724.6293 | E17: =(SUMIFS('04_Base_Despesas'!$D$4:$D$219, '04_Base_Despesas'!$A$4:$A$219, E$7, '04_Base_Despesas'!$B$4:$B$219, "marketing"))*(IFERROR(SUMIFS('03_Base_Vendas'!$I$4:$I$387, '03_Base_Vendas'!$A$4:$A$387, E$7, '03_Base_Vendas'!$B$4:$B$387, "ecommerce")/SUMIFS('03_Base_Vendas'!$I$4:$I$387, '03_Base_Vendas'!$A$4:$A$387, E$7),0)) -> 5312.2628 | F17: =(SUMIFS('04_Base_Despesas'!$D$4:$D$219, '04_Base_Despesas'!$A$4:$A$219, F$7, '04_Base_Despesas'!$B$4:$B$219, "marketing"))*(IFERROR(SUMIFS('03_Base_Vendas'!$I$4:$I$387, '03_Base_Vendas'!$A$4:$A$387, F$7, '03_Base_Vendas'!$B$4:$B$387, "ecommerce")/SUMIFS('03_Base_Vendas'!$I$4:$I$387, '03_Base_Vendas'!$A$4:$A$387, F$7),0)) -> 8328.9074 | G17: =(SUMIFS('04_Base_Despesas'!$D$4:$D$219, '04_Base_Despesas'!$A$4:$A$219, G$7, '04_Base_Despesas'!$B$4:$B$219, "marketing"))*(IFERROR(SUMIFS('03_Base_Vendas'!$I$4:$I$387, '03_Base_Vendas'!$A$4:$A$387, G$7, '03_Base_Vendas'!$B$4:$B$387, "ecommerce")/SUMIFS('03_Base_Vendas'!$I$4:$I$387, '03_Base_Vendas'!$A$4:$A$387, G$7),0)) -> 8465.773 | H17: =(SUMIFS('04_Base_Despesas'!$D$4:$D$219, '04_Base_Despesas'!$A$4:$A$219, H$7, '04_Base_Despesas'!$B$4:$B$219, "marketing"))*(IFERROR(SUMIFS('03_Base_Vendas'!$I$4:$I$387, '03_Base_Vendas'!$A$4:$A$387, H$7, '03_Base_Vendas'!$B$4:$B$387, "ecommerce")/SUMIFS('03_Base_Vendas'!$I$4:$I$387, '03_Base_Vendas'!$A$4:$A$387, H$7),0)) -> 4867.3702 | I17: =(SUMIFS('04_Base_Despesas'!$D$4:$D$219, '04_Base_Despesas'!$A$4:$A$219, I$7, '04_Base_Despesas'!$B$4:$B$219, "marketing"))*(IFERROR(SUMIFS('03_Base_Vendas'!$I$4:$I$387, '03_Base_Vendas'!$A$4:$A$387, I$7, '03_Base_Vendas'!$B$4:$B$387, "ecommerce")/SUMIFS('03_Base_Vendas'!$I$4:$I$387, '03_Base_Vendas'!$A$4:$A$387, I$7),0)) -> 5945.8051 | ... Y17: =(SUMIFS('04_Base_Despesas'!$D$4:$D$219, '04_Base_Despesas'!$A$4:$A$219, Y$7, '04_Base_Despesas'!$B$4:$B$219, "marketing"))*(IFERROR(SUMIFS('03_Base_Vendas'!$I$4:$I$387, '03_Base_Vendas'!$A$4:$A$387, Y$7, '03_Base_Vendas'!$B$4:$B$387, "ecommerce")/SUMIFS('03_Base_Vendas'!$I$4:$I$387, '03_Base_Vendas'!$A$4:$A$387, Y$7),0)) -> 7196.8572 | Z17: =SUM(B17:Y17) -> 159187.75
A18: (−) Logística | B18: =(SUMIFS('04_Base_Despesas'!$D$4:$D$219, '04_Base_Despesas'!$A$4:$A$219, B$7, '04_Base_Despesas'!$B$4:$B$219, "logistica"))*(IFERROR(SUMIFS('03_Base_Vendas'!$I$4:$I$387, '03_Base_Vendas'!$A$4:$A$387, B$7, '03_Base_Vendas'!$B$4:$B$387, "ecommerce")/SUMIFS('03_Base_Vendas'!$I$4:$I$387, '03_Base_Vendas'!$A$4:$A$387, B$7),0)) -> 3830.0842 | C18: =(SUMIFS('04_Base_Despesas'!$D$4:$D$219, '04_Base_Despesas'!$A$4:$A$219, C$7, '04_Base_Despesas'!$B$4:$B$219, "logistica"))*(IFERROR(SUMIFS('03_Base_Vendas'!$I$4:$I$387, '03_Base_Vendas'!$A$4:$A$387, C$7, '03_Base_Vendas'!$B$4:$B$387, "ecommerce")/SUMIFS('03_Base_Vendas'!$I$4:$I$387, '03_Base_Vendas'!$A$4:$A$387, C$7),0)) -> 4397.9378 | D18: =(SUMIFS('04_Base_Despesas'!$D$4:$D$219, '04_Base_Despesas'!$A$4:$A$219, D$7, '04_Base_Despesas'!$B$4:$B$219, "logistica"))*(IFERROR(SUMIFS('03_Base_Vendas'!$I$4:$I$387, '03_Base_Vendas'!$A$4:$A$387, D$7, '03_Base_Vendas'!$B$4:$B$387, "ecommerce")/SUMIFS('03_Base_Vendas'!$I$4:$I$387, '03_Base_Vendas'!$A$4:$A$387, D$7),0)) -> 4197.1864 | E18: =(SUMIFS('04_Base_Despesas'!$D$4:$D$219, '04_Base_Despesas'!$A$4:$A$219, E$7, '04_Base_Despesas'!$B$4:$B$219, "logistica"))*(IFERROR(SUMIFS('03_Base_Vendas'!$I$4:$I$387, '03_Base_Vendas'!$A$4:$A$387, E$7, '03_Base_Vendas'!$B$4:$B$387, "ecommerce")/SUMIFS('03_Base_Vendas'!$I$4:$I$387, '03_Base_Vendas'!$A$4:$A$387, E$7),0)) -> 4662.73 | F18: =(SUMIFS('04_Base_Despesas'!$D$4:$D$219, '04_Base_Despesas'!$A$4:$A$219, F$7, '04_Base_Despesas'!$B$4:$B$219, "logistica"))*(IFERROR(SUMIFS('03_Base_Vendas'!$I$4:$I$387, '03_Base_Vendas'!$A$4:$A$387, F$7, '03_Base_Vendas'!$B$4:$B$387, "ecommerce")/SUMIFS('03_Base_Vendas'!$I$4:$I$387, '03_Base_Vendas'!$A$4:$A$387, F$7),0)) -> 4805.173 | G18: =(SUMIFS('04_Base_Despesas'!$D$4:$D$219, '04_Base_Despesas'!$A$4:$A$219, G$7, '04_Base_Despesas'!$B$4:$B$219, "logistica"))*(IFERROR(SUMIFS('03_Base_Vendas'!$I$4:$I$387, '03_Base_Vendas'!$A$4:$A$387, G$7, '03_Base_Vendas'!$B$4:$B$387, "ecommerce")/SUMIFS('03_Base_Vendas'!$I$4:$I$387, '03_Base_Vendas'!$A$4:$A$387, G$7),0)) -> 4501.2821 | H18: =(SUMIFS('04_Base_Despesas'!$D$4:$D$219, '04_Base_Despesas'!$A$4:$A$219, H$7, '04_Base_Despesas'!$B$4:$B$219, "logistica"))*(IFERROR(SUMIFS('03_Base_Vendas'!$I$4:$I$387, '03_Base_Vendas'!$A$4:$A$387, H$7, '03_Base_Vendas'!$B$4:$B$387, "ecommerce")/SUMIFS('03_Base_Vendas'!$I$4:$I$387, '03_Base_Vendas'!$A$4:$A$387, H$7),0)) -> 5254.3874 | I18: =(SUMIFS('04_Base_Despesas'!$D$4:$D$219, '04_Base_Despesas'!$A$4:$A$219, I$7, '04_Base_Despesas'!$B$4:$B$219, "logistica"))*(IFERROR(SUMIFS('03_Base_Vendas'!$I$4:$I$387, '03_Base_Vendas'!$A$4:$A$387, I$7, '03_Base_Vendas'!$B$4:$B$387, "ecommerce")/SUMIFS('03_Base_Vendas'!$I$4:$I$387, '03_Base_Vendas'!$A$4:$A$387, I$7),0)) -> 4977.6995 | ... Y18: =(SUMIFS('04_Base_Despesas'!$D$4:$D$219, '04_Base_Despesas'!$A$4:$A$219, Y$7, '04_Base_Despesas'!$B$4:$B$219, "logistica"))*(IFERROR(SUMIFS('03_Base_Vendas'!$I$4:$I$387, '03_Base_Vendas'!$A$4:$A$387, Y$7, '03_Base_Vendas'!$B$4:$B$387, "ecommerce")/SUMIFS('03_Base_Vendas'!$I$4:$I$387, '03_Base_Vendas'!$A$4:$A$387, Y$7),0)) -> 4738.0743 | Z18: =SUM(B18:Y18) -> 108665.01
A19: (−) Tecnologia | B19: =(SUMIFS('04_Base_Despesas'!$D$4:$D$219, '04_Base_Despesas'!$A$4:$A$219, B$7, '04_Base_Despesas'!$B$4:$B$219, "tecnologia"))*(IFERROR(SUMIFS('03_Base_Vendas'!$I$4:$I$387, '03_Base_Vendas'!$A$4:$A$387, B$7, '03_Base_Vendas'!$B$4:$B$387, "ecommerce")/SUMIFS('03_Base_Vendas'!$I$4:$I$387, '03_Base_Vendas'!$A$4:$A$387, B$7),0)) -> 2859.612 | C19: =(SUMIFS('04_Base_Despesas'!$D$4:$D$219, '04_Base_Despesas'!$A$4:$A$219, C$7, '04_Base_Despesas'!$B$4:$B$219, "tecnologia"))*(IFERROR(SUMIFS('03_Base_Vendas'!$I$4:$I$387, '03_Base_Vendas'!$A$4:$A$387, C$7, '03_Base_Vendas'!$B$4:$B$387, "ecommerce")/SUMIFS('03_Base_Vendas'!$I$4:$I$387, '03_Base_Vendas'!$A$4:$A$387, C$7),0)) -> 3176.8432 | D19: =(SUMIFS('04_Base_Despesas'!$D$4:$D$219, '04_Base_Despesas'!$A$4:$A$219, D$7, '04_Base_Despesas'!$B$4:$B$219, "tecnologia"))*(IFERROR(SUMIFS('03_Base_Vendas'!$I$4:$I$387, '03_Base_Vendas'!$A$4:$A$387, D$7, '03_Base_Vendas'!$B$4:$B$387, "ecommerce")/SUMIFS('03_Base_Vendas'!$I$4:$I$387, '03_Base_Vendas'!$A$4:$A$387, D$7),0)) -> 2859.8909 | E19: =(SUMIFS('04_Base_Despesas'!$D$4:$D$219, '04_Base_Despesas'!$A$4:$A$219, E$7, '04_Base_Despesas'!$B$4:$B$219, "tecnologia"))*(IFERROR(SUMIFS('03_Base_Vendas'!$I$4:$I$387, '03_Base_Vendas'!$A$4:$A$387, E$7, '03_Base_Vendas'!$B$4:$B$387, "ecommerce")/SUMIFS('03_Base_Vendas'!$I$4:$I$387, '03_Base_Vendas'!$A$4:$A$387, E$7),0)) -> 2829.3629 | F19: =(SUMIFS('04_Base_Despesas'!$D$4:$D$219, '04_Base_Despesas'!$A$4:$A$219, F$7, '04_Base_Despesas'!$B$4:$B$219, "tecnologia"))*(IFERROR(SUMIFS('03_Base_Vendas'!$I$4:$I$387, '03_Base_Vendas'!$A$4:$A$387, F$7, '03_Base_Vendas'!$B$4:$B$387, "ecommerce")/SUMIFS('03_Base_Vendas'!$I$4:$I$387, '03_Base_Vendas'!$A$4:$A$387, F$7),0)) -> 3209.4647 | G19: =(SUMIFS('04_Base_Despesas'!$D$4:$D$219, '04_Base_Despesas'!$A$4:$A$219, G$7, '04_Base_Despesas'!$B$4:$B$219, "tecnologia"))*(IFERROR(SUMIFS('03_Base_Vendas'!$I$4:$I$387, '03_Base_Vendas'!$A$4:$A$387, G$7, '03_Base_Vendas'!$B$4:$B$387, "ecommerce")/SUMIFS('03_Base_Vendas'!$I$4:$I$387, '03_Base_Vendas'!$A$4:$A$387, G$7),0)) -> 3199.74 | H19: =(SUMIFS('04_Base_Despesas'!$D$4:$D$219, '04_Base_Despesas'!$A$4:$A$219, H$7, '04_Base_Despesas'!$B$4:$B$219, "tecnologia"))*(IFERROR(SUMIFS('03_Base_Vendas'!$I$4:$I$387, '03_Base_Vendas'!$A$4:$A$387, H$7, '03_Base_Vendas'!$B$4:$B$387, "ecommerce")/SUMIFS('03_Base_Vendas'!$I$4:$I$387, '03_Base_Vendas'!$A$4:$A$387, H$7),0)) -> 3240.9815 | I19: =(SUMIFS('04_Base_Despesas'!$D$4:$D$219, '04_Base_Despesas'!$A$4:$A$219, I$7, '04_Base_Despesas'!$B$4:$B$219, "tecnologia"))*(IFERROR(SUMIFS('03_Base_Vendas'!$I$4:$I$387, '03_Base_Vendas'!$A$4:$A$387, I$7, '03_Base_Vendas'!$B$4:$B$387, "ecommerce")/SUMIFS('03_Base_Vendas'!$I$4:$I$387, '03_Base_Vendas'!$A$4:$A$387, I$7),0)) -> 3144.1212 | ... Y19: =(SUMIFS('04_Base_Despesas'!$D$4:$D$219, '04_Base_Despesas'!$A$4:$A$219, Y$7, '04_Base_Despesas'!$B$4:$B$219, "tecnologia"))*(IFERROR(SUMIFS('03_Base_Vendas'!$I$4:$I$387, '03_Base_Vendas'!$A$4:$A$387, Y$7, '03_Base_Vendas'!$B$4:$B$387, "ecommerce")/SUMIFS('03_Base_Vendas'!$I$4:$I$387, '03_Base_Vendas'!$A$4:$A$387, Y$7),0)) -> 0 | Z19: =SUM(B19:Y19) -> 69563.101
A20: (−) Administrativo | B20: =(SUMIFS('04_Base_Despesas'!$D$4:$D$219, '04_Base_Despesas'!$A$4:$A$219, B$7, '04_Base_Despesas'!$B$4:$B$219, "administrativo"))*(IFERROR(SUMIFS('03_Base_Vendas'!$I$4:$I$387, '03_Base_Vendas'!$A$4:$A$387, B$7, '03_Base_Vendas'!$B$4:$B$387, "ecommerce")/SUMIFS('03_Base_Vendas'!$I$4:$I$387, '03_Base_Vendas'!$A$4:$A$387, B$7),0)) -> 1749.8608 | C20: =(SUMIFS('04_Base_Despesas'!$D$4:$D$219, '04_Base_Despesas'!$A$4:$A$219, C$7, '04_Base_Despesas'!$B$4:$B$219, "administrativo"))*(IFERROR(SUMIFS('03_Base_Vendas'!$I$4:$I$387, '03_Base_Vendas'!$A$4:$A$387, C$7, '03_Base_Vendas'!$B$4:$B$387, "ecommerce")/SUMIFS('03_Base_Vendas'!$I$4:$I$387, '03_Base_Vendas'!$A$4:$A$387, C$7),0)) -> 1200.2345 | D20: =(SUMIFS('04_Base_Despesas'!$D$4:$D$219, '04_Base_Despesas'!$A$4:$A$219, D$7, '04_Base_Despesas'!$B$4:$B$219, "administrativo"))*(IFERROR(SUMIFS('03_Base_Vendas'!$I$4:$I$387, '03_Base_Vendas'!$A$4:$A$387, D$7, '03_Base_Vendas'!$B$4:$B$387, "ecommerce")/SUMIFS('03_Base_Vendas'!$I$4:$I$387, '03_Base_Vendas'!$A$4:$A$387, D$7),0)) -> 1074.6508 | E20: =(SUMIFS('04_Base_Despesas'!$D$4:$D$219, '04_Base_Despesas'!$A$4:$A$219, E$7, '04_Base_Despesas'!$B$4:$B$219, "administrativo"))*(IFERROR(SUMIFS('03_Base_Vendas'!$I$4:$I$387, '03_Base_Vendas'!$A$4:$A$387, E$7, '03_Base_Vendas'!$B$4:$B$387, "ecommerce")/SUMIFS('03_Base_Vendas'!$I$4:$I$387, '03_Base_Vendas'!$A$4:$A$387, E$7),0)) -> 1957.0023 | F20: =(SUMIFS('04_Base_Despesas'!$D$4:$D$219, '04_Base_Despesas'!$A$4:$A$219, F$7, '04_Base_Despesas'!$B$4:$B$219, "administrativo"))*(IFERROR(SUMIFS('03_Base_Vendas'!$I$4:$I$387, '03_Base_Vendas'!$A$4:$A$387, F$7, '03_Base_Vendas'!$B$4:$B$387, "ecommerce")/SUMIFS('03_Base_Vendas'!$I$4:$I$387, '03_Base_Vendas'!$A$4:$A$387, F$7),0)) -> 1217.4957 | G20: =(SUMIFS('04_Base_Despesas'!$D$4:$D$219, '04_Base_Despesas'!$A$4:$A$219, G$7, '04_Base_Despesas'!$B$4:$B$219, "administrativo"))*(IFERROR(SUMIFS('03_Base_Vendas'!$I$4:$I$387, '03_Base_Vendas'!$A$4:$A$387, G$7, '03_Base_Vendas'!$B$4:$B$387, "ecommerce")/SUMIFS('03_Base_Vendas'!$I$4:$I$387, '03_Base_Vendas'!$A$4:$A$387, G$7),0)) -> 1193.8562 | H20: =(SUMIFS('04_Base_Despesas'!$D$4:$D$219, '04_Base_Despesas'!$A$4:$A$219, H$7, '04_Base_Despesas'!$B$4:$B$219, "administrativo"))*(IFERROR(SUMIFS('03_Base_Vendas'!$I$4:$I$387, '03_Base_Vendas'!$A$4:$A$387, H$7, '03_Base_Vendas'!$B$4:$B$387, "ecommerce")/SUMIFS('03_Base_Vendas'!$I$4:$I$387, '03_Base_Vendas'!$A$4:$A$387, H$7),0)) -> 2080.6885 | I20: =(SUMIFS('04_Base_Despesas'!$D$4:$D$219, '04_Base_Despesas'!$A$4:$A$219, I$7, '04_Base_Despesas'!$B$4:$B$219, "administrativo"))*(IFERROR(SUMIFS('03_Base_Vendas'!$I$4:$I$387, '03_Base_Vendas'!$A$4:$A$387, I$7, '03_Base_Vendas'!$B$4:$B$387, "ecommerce")/SUMIFS('03_Base_Vendas'!$I$4:$I$387, '03_Base_Vendas'!$A$4:$A$387, I$7),0)) -> 1156.82 | ... Y20: =(SUMIFS('04_Base_Despesas'!$D$4:$D$219, '04_Base_Despesas'!$A$4:$A$219, Y$7, '04_Base_Despesas'!$B$4:$B$219, "administrativo"))*(IFERROR(SUMIFS('03_Base_Vendas'!$I$4:$I$387, '03_Base_Vendas'!$A$4:$A$387, Y$7, '03_Base_Vendas'!$B$4:$B$387, "ecommerce")/SUMIFS('03_Base_Vendas'!$I$4:$I$387, '03_Base_Vendas'!$A$4:$A$387, Y$7),0)) -> 1273.2419 | Z20: =SUM(B20:Y20) -> 34165.639
